<?xml version="1.0" ?>
<!-- =================================================================================== -->
<!-- |    This document was autogenerated by xacro from /home/mathieu/work/ros-kinetic/my-bioloid/src/bioloid_typea_description/typea.xacro | -->
<!-- |    EDITING THIS FILE BY HAND IS NOT RECOMMENDED                                 | -->
<!-- =================================================================================== -->
<robot name="typea" xmlns:xacro="http://www.ros.org/wiki/xacro">
  <gazebo>
    <plugin filename="libgazebo_ros_control.so" name="gazebo_ros_control">
      <robotNamespace>/typea</robotNamespace>
      <robotSimType>gazebo_ros_control/DefaultRobotHWSim</robotSimType>
    </plugin>
  </gazebo>
  <transmission name="r_shoulder_swing_joint_tran">
    <type>transmission_interface/SimpleTransmission</type>
    <joint name="r_shoulder_swing_joint">
      <hardwareInterface>EffortJointInterface</hardwareInterface>
    </joint>
    <actuator name="r_shoulder_swing_joint_motor">
      <hardwareInterface>EffortJointInterface</hardwareInterface>
      <mechanicalReduction>1</mechanicalReduction>
    </actuator>
  </transmission>
  <transmission name="l_shoulder_swing_joint_tran">
    <type>transmission_interface/SimpleTransmission</type>
    <joint name="l_shoulder_swing_joint">
      <hardwareInterface>EffortJointInterface</hardwareInterface>
    </joint>
    <actuator name="l_shoulder_swing_joint_motor">
      <hardwareInterface>EffortJointInterface</hardwareInterface>
      <mechanicalReduction>1</mechanicalReduction>
    </actuator>
  </transmission>
  <transmission name="r_shoulder_lateral_joint_tran">
    <type>transmission_interface/SimpleTransmission</type>
    <joint name="r_shoulder_lateral_joint">
      <hardwareInterface>EffortJointInterface</hardwareInterface>
    </joint>
    <actuator name="r_shoulder_lateral_joint_motor">
      <hardwareInterface>EffortJointInterface</hardwareInterface>
      <mechanicalReduction>1</mechanicalReduction>
    </actuator>
  </transmission>
  <transmission name="l_shoulder_lateral_joint_tran">
    <type>transmission_interface/SimpleTransmission</type>
    <joint name="l_shoulder_lateral_joint">
      <hardwareInterface>EffortJointInterface</hardwareInterface>
    </joint>
    <actuator name="l_shoulder_lateral_joint_motor">
      <hardwareInterface>EffortJointInterface</hardwareInterface>
      <mechanicalReduction>1</mechanicalReduction>
    </actuator>
  </transmission>
  <transmission name="r_elbow_joint_tran">
    <type>transmission_interface/SimpleTransmission</type>
    <joint name="r_elbow_joint">
      <hardwareInterface>EffortJointInterface</hardwareInterface>
    </joint>
    <actuator name="r_elbow_joint_motor">
      <hardwareInterface>EffortJointInterface</hardwareInterface>
      <mechanicalReduction>1</mechanicalReduction>
    </actuator>
  </transmission>
  <transmission name="l_elbow_joint_tran">
    <type>transmission_interface/SimpleTransmission</type>
    <joint name="l_elbow_joint">
      <hardwareInterface>EffortJointInterface</hardwareInterface>
    </joint>
    <actuator name="l_elbow_joint_motor">
      <hardwareInterface>EffortJointInterface</hardwareInterface>
      <mechanicalReduction>1</mechanicalReduction>
    </actuator>
  </transmission>
  <transmission name="r_hip_twist_joint_tran">
    <type>transmission_interface/SimpleTransmission</type>
    <joint name="r_hip_twist_joint">
      <hardwareInterface>EffortJointInterface</hardwareInterface>
    </joint>
    <actuator name="r_hip_twist_joint_motor">
      <hardwareInterface>EffortJointInterface</hardwareInterface>
      <mechanicalReduction>1</mechanicalReduction>
    </actuator>
  </transmission>
  <transmission name="l_hip_twist_joint_tran">
    <type>transmission_interface/SimpleTransmission</type>
    <joint name="l_hip_twist_joint">
      <hardwareInterface>EffortJointInterface</hardwareInterface>
    </joint>
    <actuator name="l_hip_twist_joint_motor">
      <hardwareInterface>EffortJointInterface</hardwareInterface>
      <mechanicalReduction>1</mechanicalReduction>
    </actuator>
  </transmission>
  <transmission name="r_hip_lateral_joint_tran">
    <type>transmission_interface/SimpleTransmission</type>
    <joint name="r_hip_lateral_joint">
      <hardwareInterface>EffortJointInterface</hardwareInterface>
    </joint>
    <actuator name="r_hip_lateral_joint_motor">
      <hardwareInterface>EffortJointInterface</hardwareInterface>
      <mechanicalReduction>1</mechanicalReduction>
    </actuator>
  </transmission>
  <transmission name="l_hip_lateral_joint_tran">
    <type>transmission_interface/SimpleTransmission</type>
    <joint name="l_hip_lateral_joint">
      <hardwareInterface>EffortJointInterface</hardwareInterface>
    </joint>
    <actuator name="l_hip_lateral_joint_motor">
      <hardwareInterface>EffortJointInterface</hardwareInterface>
      <mechanicalReduction>1</mechanicalReduction>
    </actuator>
  </transmission>
  <transmission name="r_hip_swing_joint_tran">
    <type>transmission_interface/SimpleTransmission</type>
    <joint name="r_hip_swing_joint">
      <hardwareInterface>EffortJointInterface</hardwareInterface>
    </joint>
    <actuator name="r_hip_swing_joint_motor">
      <hardwareInterface>EffortJointInterface</hardwareInterface>
      <mechanicalReduction>1</mechanicalReduction>
    </actuator>
  </transmission>
  <transmission name="l_hip_swing_joint_tran">
    <type>transmission_interface/SimpleTransmission</type>
    <joint name="l_hip_swing_joint">
      <hardwareInterface>EffortJointInterface</hardwareInterface>
    </joint>
    <actuator name="l_hip_swing_joint_motor">
      <hardwareInterface>EffortJointInterface</hardwareInterface>
      <mechanicalReduction>1</mechanicalReduction>
    </actuator>
  </transmission>
  <transmission name="r_knee_joint_tran">
    <type>transmission_interface/SimpleTransmission</type>
    <joint name="r_knee_joint">
      <hardwareInterface>EffortJointInterface</hardwareInterface>
    </joint>
    <actuator name="r_knee_joint_motor">
      <hardwareInterface>EffortJointInterface</hardwareInterface>
      <mechanicalReduction>1</mechanicalReduction>
    </actuator>
  </transmission>
  <transmission name="l_knee_joint_tran">
    <type>transmission_interface/SimpleTransmission</type>
    <joint name="l_knee_joint">
      <hardwareInterface>EffortJointInterface</hardwareInterface>
    </joint>
    <actuator name="l_knee_joint_motor">
      <hardwareInterface>EffortJointInterface</hardwareInterface>
      <mechanicalReduction>1</mechanicalReduction>
    </actuator>
  </transmission>
  <transmission name="r_ankle_swing_joint_tran">
    <type>transmission_interface/SimpleTransmission</type>
    <joint name="r_ankle_swing_joint">
      <hardwareInterface>EffortJointInterface</hardwareInterface>
    </joint>
    <actuator name="r_ankle_swing_joint_motor">
      <hardwareInterface>EffortJointInterface</hardwareInterface>
      <mechanicalReduction>1</mechanicalReduction>
    </actuator>
  </transmission>
  <transmission name="l_ankle_swing_joint_tran">
    <type>transmission_interface/SimpleTransmission</type>
    <joint name="l_ankle_swing_joint">
      <hardwareInterface>EffortJointInterface</hardwareInterface>
    </joint>
    <actuator name="l_ankle_swing_joint_motor">
      <hardwareInterface>EffortJointInterface</hardwareInterface>
      <mechanicalReduction>1</mechanicalReduction>
    </actuator>
  </transmission>
  <transmission name="r_ankle_lateral_joint_tran">
    <type>transmission_interface/SimpleTransmission</type>
    <joint name="r_ankle_lateral_joint">
      <hardwareInterface>EffortJointInterface</hardwareInterface>
    </joint>
    <actuator name="r_ankle_lateral_joint_motor">
      <hardwareInterface>EffortJointInterface</hardwareInterface>
      <mechanicalReduction>1</mechanicalReduction>
    </actuator>
  </transmission>
  <transmission name="l_ankle_lateral_joint_tran">
    <type>transmission_interface/SimpleTransmission</type>
    <joint name="l_ankle_lateral_joint">
      <hardwareInterface>EffortJointInterface</hardwareInterface>
    </joint>
    <actuator name="l_ankle_lateral_joint_motor">
      <hardwareInterface>EffortJointInterface</hardwareInterface>
      <mechanicalReduction>1</mechanicalReduction>
    </actuator>
  </transmission>
  <!-- Torso -->
  <link name="torso_link">
    <visual>
      <geometry>
        <mesh filename="file:///home/mathieu/work/ros-kinetic/my-bioloid/src/bioloid_typea_description/assets/cad/BPF-CHEST-F_FCD-Conv_BDR-Col.dae" scale="0.001 0.001 0.001"/>
      </geometry>
      <origin rpy="1.57079632679 0 1.57079632679"/>
    </visual>
    <visual>
      <geometry>
        <mesh filename="file:///home/mathieu/work/ros-kinetic/my-bioloid/src/bioloid_typea_description/assets/cad/BPF-CHEST-B_FCD-Conv_BDR-Col.dae" scale="0.001 0.001 0.001"/>
      </geometry>
      <origin rpy="1.57079632679 0 1.57079632679"/>
    </visual>
    <visual>
      <geometry>
        <mesh filename="file:///home/mathieu/work/ros-kinetic/my-bioloid/src/bioloid_typea_description/assets/cad/CM-5_FCD-Conv_BDR-Col.dae" scale="0.001 0.001 0.001"/>
      </geometry>
      <origin rpy="0 3.14159265359 1.57079632679" xyz="-0.032 0 -0.015"/>
    </visual>
    <!-- Sensor 100 -->
    <visual>
      <geometry>
        <mesh filename="file:///home/mathieu/work/ros-kinetic/my-bioloid/src/bioloid_typea_description/assets/cad/AX-S1_FCD-Conv_BDR-Col.dae" scale="0.001 0.001 0.001"/>
      </geometry>
      <origin rpy="-1.57079632679 0 -1.57079632679" xyz="0 0 0.025"/>
    </visual>
    <!-- Motor 1 -->
    <visual>
      <geometry>
        <mesh filename="file:///home/mathieu/work/ros-kinetic/my-bioloid/src/bioloid_typea_description/assets/cad/AX-12_FCD-Conv_BDR-Col.dae" scale="0.001 0.001 0.001"/>
      </geometry>
      <origin rpy="1.57079632679 0 0" xyz="0 -0.032 0"/>
    </visual>
    <visual>
      <geometry>
        <mesh filename="file:///home/mathieu/work/ros-kinetic/my-bioloid/src/bioloid_typea_description/assets/cad/FP04-F3_FCD-Conv_BDR-Col.dae" scale="0.001 0.001 0.001"/>
      </geometry>
      <origin rpy="3.14159265359 -1.57079632679 1.57079632679" xyz="-0.019 -0.032 -0.0145"/>
    </visual>
    <!-- Motor 2 -->
    <visual>
      <geometry>
        <mesh filename="file:///home/mathieu/work/ros-kinetic/my-bioloid/src/bioloid_typea_description/assets/cad/AX-12_FCD-Conv_BDR-Col.dae" scale="0.001 0.001 0.001"/>
      </geometry>
      <origin rpy="1.57079632679 0 3.14159265359" xyz="0 0.032 0"/>
    </visual>
    <visual>
      <geometry>
        <mesh filename="file:///home/mathieu/work/ros-kinetic/my-bioloid/src/bioloid_typea_description/assets/cad/FP04-F3_FCD-Conv_BDR-Col.dae" scale="0.001 0.001 0.001"/>
      </geometry>
      <origin rpy="3.14159265359 -1.57079632679 1.57079632679" xyz="-0.019 0.032 -0.0145"/>
    </visual>
    <visual>
      <geometry>
        <mesh filename="file:///home/mathieu/work/ros-kinetic/my-bioloid/src/bioloid_typea_description/assets/cad/FP04-F3_FCD-Conv_BDR-Col.dae" scale="0.001 0.001 0.001"/>
      </geometry>
      <origin rpy="0 0 1.57079632679" xyz="0.0175 0 -0.0655"/>
    </visual>
    <visual>
      <geometry>
        <mesh filename="file:///home/mathieu/work/ros-kinetic/my-bioloid/src/bioloid_typea_description/assets/cad/FP04-F3_FCD-Conv_BDR-Col.dae" scale="0.001 0.001 0.001"/>
      </geometry>
      <origin rpy="0 0 -1.57079632679" xyz="-0.0175 0 -0.0655"/>
    </visual>
    <!-- Motor 7 -->
    <visual>
      <geometry>
        <mesh filename="file:///home/mathieu/work/ros-kinetic/my-bioloid/src/bioloid_typea_description/assets/cad/AX-12_FCD-Conv_BDR-Col.dae" scale="0.001 0.001 0.001"/>
      </geometry>
      <origin rpy="0 3.14159265359 3.14159265359" xyz="0 -0.0385 -0.0655"/>
    </visual>
    <!-- Motor 8 -->
    <visual>
      <geometry>
        <mesh filename="file:///home/mathieu/work/ros-kinetic/my-bioloid/src/bioloid_typea_description/assets/cad/AX-12_FCD-Conv_BDR-Col.dae" scale="0.001 0.001 0.001"/>
      </geometry>
      <origin rpy="0 3.14159265359 0" xyz="0 0.0385 -0.0655"/>
    </visual>
    <collision name="head_collision">
      <origin xyz="-0.0122 0 0.035"/>
      <geometry>
        <box size="0.054 0.033 0.044"/>
      </geometry>
    </collision>
    <collision name="torso_collision_top">
      <origin xyz="-0.019 0 -0.015"/>
      <geometry>
        <box size="0.0905 0.103 0.0635"/>
      </geometry>
    </collision>
    <collision name="torso_collision_bottom">
      <origin xyz="-0.00625 0 -0.0648"/>
      <geometry>
        <box size="0.065 0.099 0.043"/>
      </geometry>
    </collision>
    <inertial>
      <mass value="0.6954053293"/>
      <origin xyz="0.0171121538 0.0052995599 0.0016431550"/>
      <inertia ixx="10.9003247826" ixy="0.7020020095" ixz="-1.0245344637" iyy="10.6912796312" iyz="0.0302048573" izz="10.3158095391"/>
    </inertial>
    <!--
        <inertial>
            <origin xyz="-0.003053 -0.038651 -0.019268" />
            <mass value="0.97559947"/>
            <inertia ixx="3.1081800"  ixy="-0.25460189"  ixz="2.0318174" iyy="6.3787776" iyz="0.16417863" izz="5.3316425" />
        </inertial>
        -->
  </link>
  <!-- Right foot -->
  <link name="r_foot_link">
    <visual>
      <geometry>
        <mesh filename="file:///home/mathieu/work/ros-kinetic/my-bioloid/src/bioloid_typea_description/assets/cad/FP04-F12_FCD-Conv_BDR-Col.dae" scale="0.001 0.001 0.001"/>
      </geometry>
      <origin rpy="0 1.57079632679 -1.57079632679" xyz="0.0235 0 0"/>
    </visual>
    <collision name="r_foot_collision">
      <origin xyz="0.0277 0 0"/>
      <geometry>
        <box size="0.009 0.061 0.101"/>
      </geometry>
    </collision>
    <inertial>
      <mass value="0.0373560220"/>
      <origin xyz="-0.0055676472 0.0034398816 0.0028465215"/>
      <inertia ixx="0.1234423088" ixy="-0.0133733804" ixz="-0.0140420399" iyy="0.3516093267" iyz="0.0115251052" izz="0.4110130747"/>
    </inertial>
    <!--
        <inertial>
            <origin xyz="-0.025995 -0.009506 -0.000503" />
            <mass value="0.0794462"/>
            <inertia ixx="0.12079175"  ixy="-0.00079781067"  ixz="-0.00039322246" iyx="-0.00079781067" iyy="0.10885465" iyz="0.0070770117" izx="-0.00039322246" izy="0.0070770117" izz="0.041871103" />
        </inertial>
        -->
  </link>
  <!-- Left foot -->
  <link name="l_foot_link">
    <visual>
      <geometry>
        <mesh filename="file:///home/mathieu/work/ros-kinetic/my-bioloid/src/bioloid_typea_description/assets/cad/FP04-F12_FCD-Conv_BDR-Col.dae" scale="0.001 0.001 0.001"/>
      </geometry>
      <origin rpy="3.14159265359 1.57079632679 -1.57079632679" xyz="-0.0235 0 0"/>
    </visual>
    <collision name="l_foot_collision">
      <origin xyz="-0.0277 0 0"/>
      <geometry>
        <box size="0.009 0.061 0.101"/>
      </geometry>
    </collision>
    <inertial>
      <mass value="0.0373560220"/>
      <origin xyz="-0.0055676472 -0.0035014440 0.0028465215"/>
      <inertia ixx="0.1234378971" ixy="0.0133291996" ixz="-0.0140420399" iyy="0.3516092920" iyz="-0.0114926614" izz="0.4110086282"/>
    </inertial>
    <!--
        <inertial>
            <origin xyz="-0.025995 -0.009506 -0.000503" />
            <mass value="0.0794462"/>
            <inertia ixx="0.12079175"  ixy="-0.00079781067"  ixz="-0.00039322246" iyx="-0.00079781067" iyy="0.10885465" iyz="0.0070770117" izx="-0.00039322246" izy="0.0070770117" izz="0.041871103" />
        </inertial>
        -->
  </link>
  <!-- IMU -->
  <joint name="imu_to_base_joint" type="fixed">
    <parent link="imu_link"/>
    <origin rpy="0 0 0" xyz="0.01 0 0.0788"/>
    <child link="base_link"/>
  </joint>
  <link name="imu_link">
    <visual>
      <geometry>
        <box size="0.04 0.02 0.005"/>
      </geometry>
      <material name="green">
        <color rgba="0.0 1.0 0.0 1.0"/>
      </material>
    </visual>
    <!--<inertial>
            <origin xyz="0 0 0"/>
            <mass value="1.0"/>
            <inertia  ixx="0.001" ixy="0.0"  ixz="0.0"  iyy="0.001"  iyz="0.0"  izz="0.001"/>
        </inertial>-->
  </link>
  <!-- Base -->
  <joint name="base_to_torso_joint" type="fixed">
    <parent link="base_link"/>
    <origin rpy="0 0 0" xyz="0 0 0"/>
    <child link="torso_link"/>
  </joint>
  <link name="base_link">
    </link>
  <joint name="r_shoulder_swing_joint" type="revolute">
    <parent link="torso_link"/>
    <origin rpy="1.57079632679 1.57079632679 0" xyz="0 -0.032 0"/>
    <axis xyz="0 0 1"/>
    <child link="r_shoulder_swing_link"/>
    <limit effort="2.8" lower="-1" upper="1.57079632679" velocity="1.0"/>
  </joint>
  <link name="r_shoulder_swing_link">
    <visual>
      <geometry>
        <mesh filename="file:///home/mathieu/work/ros-kinetic/my-bioloid/src/bioloid_typea_description/assets/cad/FP04-F1_FCD-Conv_BDR-Col.dae" scale="0.001 0.001 0.001"/>
      </geometry>
      <origin rpy="0 3.14159265359 3.14159265359" xyz="0 0.014 0.044"/>
    </visual>
    <collision name="r_shoulder_collision">
      <origin xyz="0 0.006 0.0375"/>
      <geometry>
        <box size="0.052 0.039 0.036"/>
      </geometry>
    </collision>
    <inertial>
      <mass value="0.0119189163"/>
      <origin xyz="-0.0109359544 0.0123630374 -0.0000000007"/>
      <inertia ixx="0.0699034069" ixy="-0.0208123701" ixz="0.0000000013" iyy="0.0672109386" iyz="-0.0000000015" izz="0.0545219826"/>
    </inertial>
    <!--
        <inertial>
            <origin xyz="-0.013522619 0.010264050 0.0013935747"/>
            <mass value="0.025913024"/>
            <inertia  ixx="0.0097758165" ixy="0.0016911839"  ixz="-0.0016911839"  iyy="0.010511104"  iyz="0.00033406955"  izz="0.005476798"/>
        </inertial>
        -->
  </link>
  <joint name="l_shoulder_swing_joint" type="revolute">
    <parent link="torso_link"/>
    <origin rpy="-1.57079632679 -1.57079632679 0" xyz="0 0.032 0"/>
    <axis xyz="0 0 1"/>
    <child link="l_shoulder_swing_link"/>
    <limit effort="2.8" lower="-1" upper="1.57079632679" velocity="1.0"/>
  </joint>
  <link name="l_shoulder_swing_link">
    <visual>
      <geometry>
        <mesh filename="file:///home/mathieu/work/ros-kinetic/my-bioloid/src/bioloid_typea_description/assets/cad/FP04-F1_FCD-Conv_BDR-Col.dae" scale="0.001 0.001 0.001"/>
      </geometry>
      <origin rpy="0 3.14159265359 3.14159265359" xyz="0 0.014 0.044"/>
    </visual>
    <collision name="l_shoulder_collision">
      <origin xyz="0 0.006 0.0375"/>
      <geometry>
        <box size="0.052 0.039 0.036"/>
      </geometry>
    </collision>
    <inertial>
      <mass value="0.0119189163"/>
      <origin xyz="-0.0109359544 -0.0123630374 0.0000000007"/>
      <inertia ixx="0.0699034069" ixy="0.0208123701" ixz="-0.0000000013" iyy="0.0672109386" iyz="-0.0000000015" izz="0.0545219826"/>
    </inertial>
    <!--
        <inertial>
            <origin xyz="-0.013522619 0.010264050 0.0013935747"/>
            <mass value="0.025913024"/>
            <inertia  ixx="0.0097758165" ixy="0.0016911839"  ixz="-0.0016911839"  iyy="0.010511104"  iyz="0.00033406955"  izz="0.005476798"/>
        </inertial>
        -->
  </link>
  <joint name="r_shoulder_lateral_joint" type="revolute">
    <parent link="r_shoulder_swing_link"/>
    <origin rpy="0 -1.57079632679 0" xyz="0 0.014 0.044"/>
    <axis xyz="0 0 1"/>
    <child link="r_upper_arm_link"/>
    <limit effort="2.8" lower="-1.5" upper="1.5" velocity="1.0"/>
  </joint>
  <link name="r_upper_arm_link">
    <visual>
      <geometry>
        <mesh filename="file:///home/mathieu/work/ros-kinetic/my-bioloid/src/bioloid_typea_description/assets/cad/AX-12_FCD-Conv_BDR-Col.dae" scale="0.001 0.001 0.001"/>
      </geometry>
      <origin rpy="0 0 1.57079632679" xyz="0 0 0"/>
    </visual>
    <visual>
      <geometry>
        <mesh filename="file:///home/mathieu/work/ros-kinetic/my-bioloid/src/bioloid_typea_description/assets/cad/BPF-BU_FCD-Conv_BDR-Col.dae" scale="0.001 0.001 0.001"/>
      </geometry>
      <origin rpy="-1.57079632679 0 1.57079632679" xyz="0 0 -0.0185"/>
    </visual>
    <visual>
      <geometry>
        <mesh filename="file:///home/mathieu/work/ros-kinetic/my-bioloid/src/bioloid_typea_description/assets/cad/BPF-WA_FCD-Conv_BDR-Col.dae" scale="0.001 0.001 0.001"/>
      </geometry>
      <origin rpy="-1.57079632679 0 1.57079632679" xyz="0 0 -0.019"/>
    </visual>
    <visual>
      <geometry>
        <mesh filename="file:///home/mathieu/work/ros-kinetic/my-bioloid/src/bioloid_typea_description/assets/cad/FP04-F3_FCD-Conv_BDR-Col.dae" scale="0.001 0.001 0.001"/>
      </geometry>
      <origin rpy="0 0 1.57079632679" xyz="0.0415 0 0"/>
    </visual>
    <visual>
      <geometry>
        <mesh filename="file:///home/mathieu/work/ros-kinetic/my-bioloid/src/bioloid_typea_description/assets/cad/FP04-F2_FCD-Conv_BDR-Col.dae" scale="0.001 0.001 0.001"/>
      </geometry>
      <origin rpy="-1.57079632679 1.57079632679 1.57079632679" xyz="0.0675 0 0"/>
    </visual>
    <collision name="r_upper arm_collision_proximal">
      <origin xyz="0.0148 0 0"/>
      <geometry>
        <box size="0.054 0.033 0.044"/>
      </geometry>
    </collision>
    <collision name="r_upper arm_collision_distal">
      <origin xyz="0.0555 0 0"/>
      <geometry>
        <box size="0.047 0.033 0.052"/>
      </geometry>
    </collision>
    <inertial>
      <mass value="0.0764574147"/>
      <origin xyz="-0.0000001987 -0.0068291607 -0.0006710552"/>
      <inertia ixx="0.2746908812" ixy="0.0000041559" ixz="-0.0000007966" iyy="0.0778170043" iyz="0.0071390070" izz="0.2260347501"/>
    </inertial>
    <!--
        <inertial>
      	<origin xyz="-0.036239 0.000734 -0.000660" />
      	<mass value="0.16837715"/>
      	<inertia ixx="0.12202839"  ixy="-0.0020812626"  ixz="-0.00088143449" iyx="-0.0020812626" iyy="0.038088441" iyz="0.0018251448" izx="-0.00088143449" izy="0.0018251448" izz="0.11340830" />
        </inertial>
        -->
  </link>
  <joint name="l_shoulder_lateral_joint" type="revolute">
    <parent link="l_shoulder_swing_link"/>
    <origin rpy="0 -1.57079632679 0" xyz="0 0.014 0.044"/>
    <axis xyz="0 0 1"/>
    <child link="l_upper_arm_link"/>
    <limit effort="2.8" lower="-1.5" upper="1.5" velocity="1.0"/>
  </joint>
  <link name="l_upper_arm_link">
    <visual>
      <geometry>
        <mesh filename="file:///home/mathieu/work/ros-kinetic/my-bioloid/src/bioloid_typea_description/assets/cad/AX-12_FCD-Conv_BDR-Col.dae" scale="0.001 0.001 0.001"/>
      </geometry>
      <origin rpy="3.14159265359 0 -1.57079632679" xyz="0 0 0"/>
    </visual>
    <visual>
      <geometry>
        <mesh filename="file:///home/mathieu/work/ros-kinetic/my-bioloid/src/bioloid_typea_description/assets/cad/BPF-BU_FCD-Conv_BDR-Col.dae" scale="0.001 0.001 0.001"/>
      </geometry>
      <origin rpy="1.57079632679 0 1.57079632679" xyz="0 0 0.0185"/>
    </visual>
    <visual>
      <geometry>
        <mesh filename="file:///home/mathieu/work/ros-kinetic/my-bioloid/src/bioloid_typea_description/assets/cad/BPF-WA_FCD-Conv_BDR-Col.dae" scale="0.001 0.001 0.001"/>
      </geometry>
      <origin rpy="1.57079632679 0 1.57079632679" xyz="0 0 0.019"/>
    </visual>
    <visual>
      <geometry>
        <mesh filename="file:///home/mathieu/work/ros-kinetic/my-bioloid/src/bioloid_typea_description/assets/cad/FP04-F3_FCD-Conv_BDR-Col.dae" scale="0.001 0.001 0.001"/>
      </geometry>
      <origin rpy="3.14159265359 0 -1.57079632679" xyz="0.0415 0 0"/>
    </visual>
    <visual>
      <geometry>
        <mesh filename="file:///home/mathieu/work/ros-kinetic/my-bioloid/src/bioloid_typea_description/assets/cad/FP04-F2_FCD-Conv_BDR-Col.dae" scale="0.001 0.001 0.001"/>
      </geometry>
      <origin rpy="1.57079632679 1.57079632679 -1.57079632679" xyz="0.0675 0 0"/>
    </visual>
    <collision name="l_upper arm_collision_proximal">
      <origin xyz="0.0148 0 0"/>
      <geometry>
        <box size="0.054 0.033 0.044"/>
      </geometry>
    </collision>
    <collision name="l_upper arm_collision_distal">
      <origin xyz="0.0555 0 0"/>
      <geometry>
        <box size="0.047 0.033 0.052"/>
      </geometry>
    </collision>
    <inertial>
      <mass value="0.0764574147"/>
      <origin xyz="0.0000001987 0.0068291607 -0.0006710552"/>
      <inertia ixx="0.2746908812" ixy="0.0000041559" ixz="0.0000007966" iyy="0.0778170043" iyz="-0.0071390070" izz="0.2260347501"/>
    </inertial>
    <!--
        <inertial>
      	<origin xyz="-0.036239 0.000734 -0.000660" />
      	<mass value="0.16837715"/>
      	<inertia ixx="0.12202839"  ixy="-0.0020812626"  ixz="-0.00088143449" iyx="-0.0020812626" iyy="0.038088441" iyz="0.0018251448" izx="-0.00088143449" izy="0.0018251448" izz="0.11340830" />
        </inertial>
        -->
  </link>
  <joint name="r_elbow_joint" type="revolute">
    <parent link="r_upper_arm_link"/>
    <origin rpy="0 0 0" xyz="0.0675 0 0"/>
    <axis xyz="0 0 1"/>
    <child link="r_lower_arm_link"/>
    <limit effort="2.8" lower="-1.77" upper="1.77" velocity="1.0"/>
  </joint>
  <link name="r_lower_arm_link">
    <!-- Motor 5 -->
    <visual>
      <geometry>
        <mesh filename="file:///home/mathieu/work/ros-kinetic/my-bioloid/src/bioloid_typea_description/assets/cad/AX-12_FCD-Conv_BDR-Col.dae" scale="0.001 0.001 0.001"/>
      </geometry>
      <origin rpy="0 0 1.57079632679" xyz="0 0 0"/>
    </visual>
    <visual>
      <geometry>
        <mesh filename="file:///home/mathieu/work/ros-kinetic/my-bioloid/src/bioloid_typea_description/assets/cad/BPF-BU_FCD-Conv_BDR-Col.dae" scale="0.001 0.001 0.001"/>
      </geometry>
      <origin rpy="-1.57079632679 0 1.57079632679" xyz="0 0 -0.0185"/>
    </visual>
    <visual>
      <geometry>
        <mesh filename="file:///home/mathieu/work/ros-kinetic/my-bioloid/src/bioloid_typea_description/assets/cad/BPF-WA_FCD-Conv_BDR-Col.dae" scale="0.001 0.001 0.001"/>
      </geometry>
      <origin rpy="-1.57079632679 0 1.57079632679" xyz="0 0 -0.019"/>
    </visual>
    <visual>
      <geometry>
        <mesh filename="file:///home/mathieu/work/ros-kinetic/my-bioloid/src/bioloid_typea_description/assets/cad/FP04-F3_FCD-Conv_BDR-Col.dae" scale="0.001 0.001 0.001"/>
      </geometry>
      <origin rpy="0 0 1.57079632679" xyz="0.0415 0 0"/>
    </visual>
    <collision name="r_lower_arm_collision">
      <origin xyz="0.017 0 0"/>
      <geometry>
        <box size="0.058 0.033 0.044"/>
      </geometry>
    </collision>
    <inertial>
      <mass value="0.0706166158"/>
      <origin xyz="-0.0004650645 -0.0046453116 -0.0005062069"/>
      <inertia ixx="0.1616520824" ixy="0.0152109261" ixz="0.0001440817" iyy="0.0418097664" iyz="0.0042626086" izz="0.1456557322"/>
    </inertial>
    <!--
        <inertial>
            <origin xyz="0.000000 0.000000 0.000000" />
            <mass value="0.059288504"/>
            <inertia ixx="0.086855267"  ixy="0.0053020311"  ixz="0.00043636051" iyx="0.0053020311" iyy="0.021192085" iyz="-0.0064855932" izx="0.00043636051" izy="-0.0064855932" izz="0.086845450" />
        </inertial>
        -->
  </link>
  <joint name="l_elbow_joint" type="revolute">
    <parent link="l_upper_arm_link"/>
    <origin rpy="0 0 0" xyz="0.0675 0 0"/>
    <axis xyz="0 0 1"/>
    <child link="l_lower_arm_link"/>
    <limit effort="2.8" lower="-1.77" upper="1.77" velocity="1.0"/>
  </joint>
  <link name="l_lower_arm_link">
    <!-- Motor 6 -->
    <visual>
      <geometry>
        <mesh filename="file:///home/mathieu/work/ros-kinetic/my-bioloid/src/bioloid_typea_description/assets/cad/AX-12_FCD-Conv_BDR-Col.dae" scale="0.001 0.001 0.001"/>
      </geometry>
      <origin rpy="3.14159265359 0 -1.57079632679" xyz="0 0 0"/>
    </visual>
    <visual>
      <geometry>
        <mesh filename="file:///home/mathieu/work/ros-kinetic/my-bioloid/src/bioloid_typea_description/assets/cad/BPF-BU_FCD-Conv_BDR-Col.dae" scale="0.001 0.001 0.001"/>
      </geometry>
      <origin rpy="1.57079632679 0 1.57079632679" xyz="0 0 0.0185"/>
    </visual>
    <visual>
      <geometry>
        <mesh filename="file:///home/mathieu/work/ros-kinetic/my-bioloid/src/bioloid_typea_description/assets/cad/BPF-WA_FCD-Conv_BDR-Col.dae" scale="0.001 0.001 0.001"/>
      </geometry>
      <origin rpy="1.57079632679 0 1.57079632679" xyz="0 0 0.019"/>
    </visual>
    <visual>
      <geometry>
        <mesh filename="file:///home/mathieu/work/ros-kinetic/my-bioloid/src/bioloid_typea_description/assets/cad/FP04-F3_FCD-Conv_BDR-Col.dae" scale="0.001 0.001 0.001"/>
      </geometry>
      <origin rpy="3.14159265359 0 -1.57079632679" xyz="0.0415 0 0"/>
    </visual>
    <collision name="l_lower_arm_collision">
      <origin xyz="0.017 0 0"/>
      <geometry>
        <box size="0.058 0.033 0.044"/>
      </geometry>
    </collision>
    <inertial>
      <mass value="0.0764574147"/>
      <origin xyz="0.0000001987 0.0068291607 -0.0006710552"/>
      <inertia ixx="0.2746908812" ixy="0.0000041559" ixz="0.0000007966" iyy="0.0778170043" iyz="-0.0071390070" izz="0.2260347501"/>
    </inertial>
    <!--
        <inertial>
            <origin xyz="0.000000 0.000000 0.000000" />
            <mass value="0.059288504"/>
            <inertia ixx="0.086855267"  ixy="0.0053020311"  ixz="0.00043636051" iyx="0.0053020311" iyy="0.021192085" iyz="-0.0064855932" izx="0.00043636051" izy="-0.0064855932" izz="0.086845450" />
        </inertial>
        -->
  </link>
  <joint name="r_hand_joint" type="fixed">
    <parent link="r_lower_arm_link"/>
    <origin rpy="0 0 0" xyz="0 0 0"/>
    <child link="r_hand_link"/>
  </joint>
  <link name="r_hand_link">
    <visual>
      <geometry>
        <mesh filename="file:///home/mathieu/work/ros-kinetic/my-bioloid/src/bioloid_typea_description/assets/cad/FP04-F11_FCD-Conv_BDR-Col.dae" scale="0.001 0.001 0.001"/>
      </geometry>
      <origin rpy="3.14159265359 -1.57079632679 0" xyz="0.0415 0 0"/>
    </visual>
    <collision name="r_palm_collision">
      <origin xyz="0.039 0 0"/>
      <geometry>
        <box size="0.0131 0.0265 0.044"/>
      </geometry>
    </collision>
    <collision name="r_fingers_collision">
      <origin xyz="0.0701 -0.0077 0"/>
      <geometry>
        <box size="0.0575 0.0175 0.035"/>
      </geometry>
    </collision>
    <inertial>
      <mass value="0.0060600633"/>
      <origin xyz="-0.0070414665 -0.0217364083 -0.0000000095"/>
      <inertia ixx="0.0544481426" ixy="0.0112666910" ixz="0.0000000167" iyy="0.0132209786" iyz="-0.0000000248" izz="0.0537569983"/>
    </inertial>
    <!--
        <inertial>
            <origin xyz="0.045838 -0.013490 0.006666"/>
            <mass value="0.010"/>
            <inertia ixx="0.12202839"  ixy="-0.0020812626"  ixz="-0.00088143449" iyx="-0.0020812626" iyy="0.038088441" iyz="0.0018251448" izx="-0.00088143449" izy="0.0018251448" izz="0.11340830" />
        </inertial>
        -->
  </link>
  <joint name="l_hand_joint" type="fixed">
    <parent link="l_lower_arm_link"/>
    <origin rpy="0 0 0" xyz="0 0 0"/>
    <child link="l_hand_link"/>
  </joint>
  <link name="l_hand_link">
    <visual>
      <geometry>
        <mesh filename="file:///home/mathieu/work/ros-kinetic/my-bioloid/src/bioloid_typea_description/assets/cad/FP04-F11_FCD-Conv_BDR-Col.dae" scale="0.001 0.001 0.001"/>
      </geometry>
      <origin rpy="0 -1.57079632679 3.14159265359" xyz="0.0415 0 0"/>
    </visual>
    <collision name="l_palm_collision">
      <origin xyz="0.039 0 0"/>
      <geometry>
        <box size="0.0131 0.0265 0.044"/>
      </geometry>
    </collision>
    <collision name="l_fingers_collision">
      <origin xyz="0.0701 -0.0077 0"/>
      <geometry>
        <box size="0.0575 0.0175 0.035"/>
      </geometry>
    </collision>
    <inertial>
      <mass value="0.0060600633"/>
      <origin xyz="-0.0070414665 0.0217364083 0.0000000095"/>
      <inertia ixx="0.0544481426" ixy="-0.0112666910" ixz="-0.0000000167" iyy="0.0132209786" iyz="-0.0000000248" izz="0.0537569983"/>
    </inertial>
    <!--
        <inertial>
            <origin xyz="0.045838 -0.013490 0.006666"/>
            <mass value="0.010"/>
            <inertia ixx="0.12202839"  ixy="-0.0020812626"  ixz="-0.00088143449" iyx="-0.0020812626" iyy="0.038088441" iyz="0.0018251448" izx="-0.00088143449" izy="0.0018251448" izz="0.11340830" />
        </inertial>
        -->
  </link>
  <joint name="r_hip_twist_joint" type="revolute">
    <parent link="torso_link"/>
    <origin rpy="0 3.14159265359 1.57079632679" xyz="0 -0.0385 -0.0655"/>
    <axis xyz="0 0 1"/>
    <child link="r_hip_twist_link"/>
    <limit effort="10" lower="-0.5" upper="0.5" velocity="5.6548668"/>
  </joint>
  <link name="r_hip_twist_link">
    <visual>
      <geometry>
        <mesh filename="file:///home/mathieu/work/ros-kinetic/my-bioloid/src/bioloid_typea_description/assets/cad/FP04-F5_FCD-Conv_BDR-Col.dae" scale="0.001 0.001 0.001"/>
      </geometry>
      <origin rpy="3.14159265359 0 3.14159265359" xyz="0 0.02 0.05"/>
    </visual>
    <collision name="r_hip_twist_collision">
      <origin xyz="0.0008 0.02 0.041"/>
      <geometry>
        <box size="0.029 0.083 0.0405"/>
      </geometry>
    </collision>
    <inertial>
      <mass value="0.0151038725"/>
      <origin xyz="0.0005416307 -0.0000009200 0.0190685105"/>
      <inertia ixx="0.0827503154" ixy="-0.0000010513" ixz="0.0026811928" iyy="0.1948149839" iyz="-0.0000055021" izz="0.1336776164"/>
    </inertial>
    <!--
        <inertial>
            <origin xyz="0.000000 0.000480 0.018437" />
            <mass value="0.167"/>
            <inertia ixx="0.12259691"  ixy="0.00071127469"  ixz="0.00081143913" iyx="0.00071127469" iyy="0.11066637" iyz="-0.0071635476" izx="0.00081143913" izy="-0.0071635476" izz="0.041877668" />
        </inertial>
        -->
  </link>
  <joint name="l_hip_twist_joint" type="revolute">
    <parent link="torso_link"/>
    <origin rpy="0 3.14159265359 -1.57079632679" xyz="0 0.0385 -0.0655"/>
    <axis xyz="0 0 1"/>
    <child link="l_hip_twist_link"/>
    <limit effort="10" lower="-0.5" upper="0.5" velocity="5.6548668"/>
  </joint>
  <link name="l_hip_twist_link">
    <visual>
      <geometry>
        <mesh filename="file:///home/mathieu/work/ros-kinetic/my-bioloid/src/bioloid_typea_description/assets/cad/FP04-F5_FCD-Conv_BDR-Col.dae" scale="0.001 0.001 0.001"/>
      </geometry>
      <origin rpy="3.14159265359 0 0.0" xyz="0 -0.02 0.05"/>
    </visual>
    <collision name="r_hip_twist_collision">
      <origin xyz="0.0008 -0.02 0.041"/>
      <geometry>
        <box size="0.029 0.083 0.0405"/>
      </geometry>
    </collision>
    <inertial>
      <mass value="0.0151038725"/>
      <origin xyz="0.0005416307 -0.0000009200 0.0190685105"/>
      <inertia ixx="0.0827503154" ixy="-0.0000010513" ixz="0.0026811928" iyy="0.1948149839" iyz="-0.0000055021" izz="0.1336776164"/>
    </inertial>
    <!--
        <inertial>
            <origin xyz="0.000000 0.000480 0.018437" />
            <mass value="0.167"/>
            <inertia ixx="0.12259691"  ixy="0.00071127469"  ixz="0.00081143913" iyx="0.00071127469" iyy="0.11066637" iyz="-0.0071635476" izx="0.00081143913" izy="-0.0071635476" izz="0.041877668" />
        </inertial>
        -->
  </link>
  <joint name="r_hip_lateral_joint" type="revolute">
    <parent link="r_hip_twist_link"/>
    <origin rpy="-1.57079632679 0 0" xyz="0 0 0.05"/>
    <axis xyz="0 0 1"/>
    <child link="r_hip_lateral_link"/>
    <limit effort="10" lower="-0.6" upper="0.6" velocity="5.6548668"/>
  </joint>
  <link name="r_hip_lateral_link">
    <!-- Motor 9[r] 10[l] -->
    <visual>
      <geometry>
        <mesh filename="file:///home/mathieu/work/ros-kinetic/my-bioloid/src/bioloid_typea_description/assets/cad/AX-12_FCD-Conv_BDR-Col.dae" scale="0.001 0.001 0.001"/>
      </geometry>
      <origin rpy="0 0 -0.0" xyz="0 0 0.0353"/>
    </visual>
    <visual>
      <geometry>
        <mesh filename="file:///home/mathieu/work/ros-kinetic/my-bioloid/src/bioloid_typea_description/assets/cad/FP04-F6_FCD-Conv_BDR-Col.dae" scale="0.001 0.001 0.001"/>
      </geometry>
      <origin rpy="0 -1.57079632679 -1.57079632679" xyz="-0.019 -0.0145 0.0513"/>
    </visual>
    <visual>
      <geometry>
        <mesh filename="file:///home/mathieu/work/ros-kinetic/my-bioloid/src/bioloid_typea_description/assets/cad/FP04-F6_FCD-Conv_BDR-Col.dae" scale="0.001 0.001 0.001"/>
      </geometry>
      <origin rpy="0 -1.57079632679 1.57079632679" xyz="0.019 -0.0145 0.0513"/>
    </visual>
    <!-- Motor 11[r] 12[l] -->
    <visual>
      <geometry>
        <mesh filename="file:///home/mathieu/work/ros-kinetic/my-bioloid/src/bioloid_typea_description/assets/cad/AX-12_FCD-Conv_BDR-Col.dae" scale="0.001 0.001 0.001"/>
      </geometry>
      <origin rpy="-0.0 -1.57079632679 0" xyz="0 0 0.0033"/>
    </visual>
    <visual>
      <geometry>
        <mesh filename="file:///home/mathieu/work/ros-kinetic/my-bioloid/src/bioloid_typea_description/assets/cad/BPF-BU_FCD-Conv_BDR-Col.dae" scale="0.001 0.001 0.001"/>
      </geometry>
      <origin rpy="-1.57079632679 -0.0 0" xyz="0 0 -0.0147"/>
    </visual>
    <visual>
      <geometry>
        <mesh filename="file:///home/mathieu/work/ros-kinetic/my-bioloid/src/bioloid_typea_description/assets/cad/FP04-F7_FCD-Conv_BDR-Col.dae" scale="0.001 0.001 0.001"/>
      </geometry>
      <origin rpy="1.57079632679 -0.0 1.57079632679" xyz="0 -0.0145 -0.0157"/>
    </visual>
    <collision name="r_hip_lateral_collision">
      <origin xyz="0 -0.0135 0.02"/>
      <geometry>
        <box size="0.04 0.051 0.0721"/>
      </geometry>
    </collision>
    <inertial>
      <mass value="0.1370485873"/>
      <origin xyz="0.0175503800 -0.0000382013 0.0012148213"/>
      <inertia ixx="0.1126701697" ixy="0.0091785729" ixz="0.0436618956" iyy="0.9538828186" iyz="-0.0012283871" izz="0.9645318393"/>
    </inertial>
    <!--
        <inertial>
            <origin xyz="0.000079 0.018242 0.013873" />
            <mass value="0.11904336"/>
            <inertia ixx="0.097950272"  ixy="0.0012119368"  ixz="-0.00021223016" iyx="0.00122119368" iyy="0.032848287" iyz="-0.0019474021" izx="-0.00021223016" izy="-0.0019474021" izz="0.11493509" />
        </inertial>
        -->
  </link>
  <joint name="l_hip_lateral_joint" type="revolute">
    <parent link="l_hip_twist_link"/>
    <origin rpy="1.57079632679 0 0" xyz="0 0 0.05"/>
    <axis xyz="0 0 1"/>
    <child link="l_hip_lateral_link"/>
    <limit effort="10" lower="-0.6" upper="0.6" velocity="5.6548668"/>
  </joint>
  <link name="l_hip_lateral_link">
    <!-- Motor 9[r] 10[l] -->
    <visual>
      <geometry>
        <mesh filename="file:///home/mathieu/work/ros-kinetic/my-bioloid/src/bioloid_typea_description/assets/cad/AX-12_FCD-Conv_BDR-Col.dae" scale="0.001 0.001 0.001"/>
      </geometry>
      <origin rpy="0 0 3.14159265359" xyz="0 0 0.0353"/>
    </visual>
    <visual>
      <geometry>
        <mesh filename="file:///home/mathieu/work/ros-kinetic/my-bioloid/src/bioloid_typea_description/assets/cad/FP04-F6_FCD-Conv_BDR-Col.dae" scale="0.001 0.001 0.001"/>
      </geometry>
      <origin rpy="0 -1.57079632679 1.57079632679" xyz="0.019 0.0145 0.0513"/>
    </visual>
    <visual>
      <geometry>
        <mesh filename="file:///home/mathieu/work/ros-kinetic/my-bioloid/src/bioloid_typea_description/assets/cad/FP04-F6_FCD-Conv_BDR-Col.dae" scale="0.001 0.001 0.001"/>
      </geometry>
      <origin rpy="0 -1.57079632679 -1.57079632679" xyz="-0.019 0.0145 0.0513"/>
    </visual>
    <!-- Motor 11[r] 12[l] -->
    <visual>
      <geometry>
        <mesh filename="file:///home/mathieu/work/ros-kinetic/my-bioloid/src/bioloid_typea_description/assets/cad/AX-12_FCD-Conv_BDR-Col.dae" scale="0.001 0.001 0.001"/>
      </geometry>
      <origin rpy="3.14159265359 1.57079632679 0" xyz="0 0 0.0033"/>
    </visual>
    <visual>
      <geometry>
        <mesh filename="file:///home/mathieu/work/ros-kinetic/my-bioloid/src/bioloid_typea_description/assets/cad/BPF-BU_FCD-Conv_BDR-Col.dae" scale="0.001 0.001 0.001"/>
      </geometry>
      <origin rpy="1.57079632679 3.14159265359 0" xyz="0 0 -0.0147"/>
    </visual>
    <visual>
      <geometry>
        <mesh filename="file:///home/mathieu/work/ros-kinetic/my-bioloid/src/bioloid_typea_description/assets/cad/FP04-F7_FCD-Conv_BDR-Col.dae" scale="0.001 0.001 0.001"/>
      </geometry>
      <origin rpy="-1.57079632679 3.14159265359 1.57079632679" xyz="0 0.0145 -0.0157"/>
    </visual>
    <collision name="r_hip_lateral_collision">
      <origin xyz="0 0.0135 0.02"/>
      <geometry>
        <box size="0.04 0.051 0.0721"/>
      </geometry>
    </collision>
    <inertial>
      <mass value="0.1370485873"/>
      <origin xyz="0.0175505223 -0.0009625287 0.0012148213"/>
      <inertia ixx="0.1139696886" ixy="-0.0332585730" ixz="0.0436616116" iyy="0.9538957327" iyz="-0.0004562535" izz="0.9658449360"/>
    </inertial>
    <!--
        <inertial>
            <origin xyz="0.000079 0.018242 0.013873" />
            <mass value="0.11904336"/>
            <inertia ixx="0.097950272"  ixy="0.0012119368"  ixz="-0.00021223016" iyx="0.00122119368" iyy="0.032848287" iyz="-0.0019474021" izx="-0.00021223016" izy="-0.0019474021" izz="0.11493509" />
        </inertial>
        -->
  </link>
  <joint name="r_hip_swing_joint" type="revolute">
    <parent link="r_hip_lateral_link"/>
    <origin rpy="1.57079632679 0 -1.57079632679" xyz="0 0 0"/>
    <axis xyz="0 0 1"/>
    <child link="r_upper_leg_link"/>
    <limit effort="10" lower="-2.0" upper="0.4" velocity="5.6548668"/>
  </joint>
  <link name="r_upper_leg_link">
    <visual>
      <geometry>
        <mesh filename="file:///home/mathieu/work/ros-kinetic/my-bioloid/src/bioloid_typea_description/assets/cad/FP04-F4_FCD-Conv_BDR-Col.dae" scale="0.001 0.001 0.001"/>
      </geometry>
      <origin rpy="-1.57079632679 -1.57079632679 -1.57079632679" xyz="0 0 0"/>
    </visual>
    <visual>
      <geometry>
        <mesh filename="file:///home/mathieu/work/ros-kinetic/my-bioloid/src/bioloid_typea_description/assets/cad/FP04-F1_FCD-Conv_BDR-Col.dae" scale="0.001 0.001 0.001"/>
      </geometry>
      <origin rpy="1.57079632679 1.57079632679 -1.57079632679" xyz="0.075 0.0145 0"/>
    </visual>
    <collision name="r_upper_leg_proximal_collision">
      <origin xyz="0.0214 0 0"/>
      <geometry>
        <box size="0.065 0.03 0.049"/>
      </geometry>
    </collision>
    <collision name="r_upper_leg_distal_collision">
      <origin xyz="0.0675 0.0065 0"/>
      <geometry>
        <box size="0.04 0.0371 0.049"/>
      </geometry>
    </collision>
    <inertial>
      <mass value="0.0311530844"/>
      <origin xyz="-0.0012110096 0.0000000568 -0.0444074895"/>
      <inertia ixx="0.8679755381" ixy="-0.0000002549" ixz="0.0306862669" iyy="0.7840055957" iyz="-0.0000008749" izz="0.1386795334"/>
    </inertial>
    <!--
        <inertial>
            <origin xyz="-0.062965 -0.000323 0.000692" />
            <mass value="0.11904336"/>
            <inertia ixx="0.097950272"  ixy="0.0012119368"  ixz="-0.00021223016" iyx="0.00122119368" iyy="0.032848287" iyz="-0.0019474021" izx="-0.00021223016" izy="-0.0019474021" izz="0.11493509" />
        </inertial>
        -->
  </link>
  <joint name="l_hip_swing_joint" type="revolute">
    <parent link="l_hip_lateral_link"/>
    <origin rpy="1.57079632679 0 -1.57079632679" xyz="0 0 0"/>
    <axis xyz="0 0 1"/>
    <child link="l_upper_leg_link"/>
    <limit effort="10" lower="-0.4" upper="2.0" velocity="5.6548668"/>
  </joint>
  <link name="l_upper_leg_link">
    <visual>
      <geometry>
        <mesh filename="file:///home/mathieu/work/ros-kinetic/my-bioloid/src/bioloid_typea_description/assets/cad/FP04-F4_FCD-Conv_BDR-Col.dae" scale="0.001 0.001 0.001"/>
      </geometry>
      <origin rpy="1.57079632679 1.57079632679 -1.57079632679" xyz="0 0 0"/>
    </visual>
    <visual>
      <geometry>
        <mesh filename="file:///home/mathieu/work/ros-kinetic/my-bioloid/src/bioloid_typea_description/assets/cad/FP04-F1_FCD-Conv_BDR-Col.dae" scale="0.001 0.001 0.001"/>
      </geometry>
      <origin rpy="1.57079632679 -1.57079632679 1.57079632679" xyz="-0.075 0.0145 0"/>
    </visual>
    <collision name="r_upper_leg_proximal_collision">
      <origin xyz="-0.0214 0 0"/>
      <geometry>
        <box size="0.065 0.03 0.049"/>
      </geometry>
    </collision>
    <collision name="r_upper_leg_distal_collision">
      <origin xyz="-0.0675 0.0065 0"/>
      <geometry>
        <box size="0.04 0.0371 0.049"/>
      </geometry>
    </collision>
    <inertial>
      <mass value="0.0311530844"/>
      <origin xyz="-0.0012110096 0.0000000568 -0.0444074895"/>
      <inertia ixx="0.8679755381" ixy="-0.0000002549" ixz="0.0306862669" iyy="0.7840055957" iyz="-0.0000008749" izz="0.1386795334"/>
    </inertial>
    <!--
        <inertial>
            <origin xyz="-0.062965 -0.000323 0.000692" />
            <mass value="0.11904336"/>
            <inertia ixx="0.097950272"  ixy="0.0012119368"  ixz="-0.00021223016" iyx="0.00122119368" iyy="0.032848287" iyz="-0.0019474021" izx="-0.00021223016" izy="-0.0019474021" izz="0.11493509" />
        </inertial>
        -->
  </link>
  <joint name="r_knee_joint" type="revolute">
    <parent link="r_upper_leg_link"/>
    <origin rpy="0 0 0" xyz="0.075 0.0145 0"/>
    <axis xyz="0 0 1"/>
    <child link="r_lower_leg_link"/>
    <limit effort="10" lower="0" upper="2" velocity="5.6548668"/>
  </joint>
  <link name="r_lower_leg_link">
    <!-- Motor 13[r] 14[l] -->
    <visual>
      <geometry>
        <mesh filename="file:///home/mathieu/work/ros-kinetic/my-bioloid/src/bioloid_typea_description/assets/cad/AX-12_FCD-Conv_BDR-Col.dae" scale="0.001 0.001 0.001"/>
      </geometry>
      <origin rpy="0 0 0" xyz="0 0 0"/>
    </visual>
    <visual>
      <geometry>
        <mesh filename="file:///home/mathieu/work/ros-kinetic/my-bioloid/src/bioloid_typea_description/assets/cad/FP04-F3_FCD-Conv_BDR-Col.dae" scale="0.001 0.001 0.001"/>
      </geometry>
      <origin rpy="0 0 1.57079632679" xyz="0.019 -0.0145 0"/>
    </visual>
    <visual>
      <geometry>
        <mesh filename="file:///home/mathieu/work/ros-kinetic/my-bioloid/src/bioloid_typea_description/assets/cad/FP04-F4_FCD-Conv_BDR-Col.dae" scale="0.001 0.001 0.001"/>
      </geometry>
      <origin rpy="1.57079632679 1.57079632679 -1.57079632679" xyz="0.071 -0.0145 0"/>
    </visual>
    <collision name="r_lower_leg_proximal_collision">
      <origin xyz="0 -0.0135 0"/>
      <geometry>
        <box size="0.033 0.051 0.044"/>
      </geometry>
    </collision>
    <collision name="r_lower_leg_distal_collision">
      <origin xyz="0.0492 -0.0145 0"/>
      <geometry>
        <box size="0.067 0.03 0.049"/>
      </geometry>
    </collision>
    <inertial>
      <mass value="0.0865217867"/>
      <origin xyz="-0.0010052497 -0.0012675002 -0.0110864417"/>
      <inertia ixx="0.5429248510" ixy="0.0021159868" ixz="0.0108877466" iyy="0.4793274318" iyz="0.0191858920" izz="0.1374253618"/>
    </inertial>
    <!--
        <inertial>
            <origin xyz="-0.053955 0.006548 -0.000592" />
            <mass value="0.070309794"/>
            <inertia ixx="0.093369608"  ixy="-0.00093567395"  ixz="-0.00023992085" iyx="-0.00093567395" iyy="0.046295534" iyz="-0.012858493" izx="-0.00023992085" izy="-0.012858493" izz="0.11351516" />
        </inertial>
        -->
  </link>
  <joint name="l_knee_joint" type="revolute">
    <parent link="l_upper_leg_link"/>
    <origin rpy="0 0 0" xyz="-0.075 0.0145 0"/>
    <axis xyz="0 0 1"/>
    <child link="l_lower_leg_link"/>
    <limit effort="10" lower="-2" upper="0" velocity="5.6548668"/>
  </joint>
  <link name="l_lower_leg_link">
    <!-- Motor 13[r] 14[l] -->
    <visual>
      <geometry>
        <mesh filename="file:///home/mathieu/work/ros-kinetic/my-bioloid/src/bioloid_typea_description/assets/cad/AX-12_FCD-Conv_BDR-Col.dae" scale="0.001 0.001 0.001"/>
      </geometry>
      <origin rpy="0 0 0" xyz="0 0 0"/>
    </visual>
    <visual>
      <geometry>
        <mesh filename="file:///home/mathieu/work/ros-kinetic/my-bioloid/src/bioloid_typea_description/assets/cad/FP04-F3_FCD-Conv_BDR-Col.dae" scale="0.001 0.001 0.001"/>
      </geometry>
      <origin rpy="0 0 -1.57079632679" xyz="-0.019 -0.0145 0"/>
    </visual>
    <visual>
      <geometry>
        <mesh filename="file:///home/mathieu/work/ros-kinetic/my-bioloid/src/bioloid_typea_description/assets/cad/FP04-F4_FCD-Conv_BDR-Col.dae" scale="0.001 0.001 0.001"/>
      </geometry>
      <origin rpy="-1.57079632679 -1.57079632679 -1.57079632679" xyz="-0.071 -0.0145 0"/>
    </visual>
    <collision name="r_lower_leg_proximal_collision">
      <origin xyz="0 -0.0135 0"/>
      <geometry>
        <box size="0.033 0.051 0.044"/>
      </geometry>
    </collision>
    <collision name="r_lower_leg_distal_collision">
      <origin xyz="-0.0492 -0.0145 0"/>
      <geometry>
        <box size="0.067 0.03 0.049"/>
      </geometry>
    </collision>
    <inertial>
      <mass value="0.0865217867"/>
      <origin xyz="-0.0010052497 0.0002674591 -0.0110862163"/>
      <inertia ixx="0.5415965019" ixy="-0.0012456852" ixz="0.0108877802" iyy="0.4793274729" iyz="-0.0095904753" izz="0.1360973080"/>
    </inertial>
    <!--
        <inertial>
            <origin xyz="-0.053955 0.006548 -0.000592" />
            <mass value="0.070309794"/>
            <inertia ixx="0.093369608"  ixy="-0.00093567395"  ixz="-0.00023992085" iyx="-0.00093567395" iyy="0.046295534" iyz="-0.012858493" izx="-0.00023992085" izy="-0.012858493" izz="0.11351516" />
        </inertial>
        -->
  </link>
  <joint name="r_ankle_swing_joint" type="revolute">
    <parent link="r_lower_leg_link"/>
    <origin rpy="3.14159265359 0 0" xyz="0.071 -0.0145 0"/>
    <axis xyz="0 0 1"/>
    <child link="r_ankle_swing_link"/>
    <limit effort="10" lower="-0.4" upper="2.0" velocity="5.6548668"/>
  </joint>
  <link name="r_ankle_swing_link">
    <!-- Motor 15[r] 16[l] -->
    <visual>
      <geometry>
        <mesh filename="file:///home/mathieu/work/ros-kinetic/my-bioloid/src/bioloid_typea_description/assets/cad/AX-12_FCD-Conv_BDR-Col.dae" scale="0.001 0.001 0.001"/>
      </geometry>
      <origin rpy=" -0.0  3.14159265359 -1.57079632679" xyz="0 0 0"/>
    </visual>
    <visual>
      <geometry>
        <mesh filename="file:///home/mathieu/work/ros-kinetic/my-bioloid/src/bioloid_typea_description/assets/cad/FP04-F7_FCD-Conv_BDR-Col.dae" scale="0.001 0.001 0.001"/>
      </geometry>
      <origin rpy="3.14159265359 -0.0 0" xyz="-0.0145 0.019 0"/>
    </visual>
    <!-- Motor 17[r] 18[l] -->
    <visual>
      <geometry>
        <mesh filename="file:///home/mathieu/work/ros-kinetic/my-bioloid/src/bioloid_typea_description/assets/cad/AX-12_FCD-Conv_BDR-Col.dae" scale="0.001 0.001 0.001"/>
      </geometry>
      <origin rpy="0 1.57079632679 -1.57079632679" xyz="0 -0.032 0"/>
    </visual>
    <visual>
      <geometry>
        <mesh filename="file:///home/mathieu/work/ros-kinetic/my-bioloid/src/bioloid_typea_description/assets/cad/FP04-F6_FCD-Conv_BDR-Col.dae" scale="0.001 0.001 0.001"/>
      </geometry>
      <origin rpy="-1.57079632679 0 -1.57079632679" xyz="-0.0145 -0.048 0.019"/>
    </visual>
    <visual>
      <geometry>
        <mesh filename="file:///home/mathieu/work/ros-kinetic/my-bioloid/src/bioloid_typea_description/assets/cad/FP04-F6_FCD-Conv_BDR-Col.dae" scale="0.001 0.001 0.001"/>
      </geometry>
      <origin rpy="1.57079632679 0 -1.57079632679" xyz="-0.0145 -0.048 -0.019"/>
    </visual>
    <collision name="r_ankle_swing_collision">
      <origin xyz="-0.0135 -0.0167 0"/>
      <geometry>
        <box size="0.051 0.0721 0.04"/>
      </geometry>
    </collision>
    <inertial>
      <mass value="0.1370485873"/>
      <origin xyz="0.0175505223 0.0009625287 -0.0012148213"/>
      <inertia ixx="0.1139696886" ixy="0.0332585730" ixz="-0.0436616116" iyy="0.9538957327" iyz="-0.0004562535" izz="0.9658449360"/>
    </inertial>
    <!--
        <inertial>
            <origin xyz="-0.000214 -0.018536 0.013873" />
            <mass value="0.16710792"/>
            <inertia ixx="0.12079175"  ixy="-0.00079781067"  ixz="-0.00039322246" iyx="-0.00079781067" iyy="0.10885465" iyz="0.0070770117" izx="-0.00039322246" izy="0.0070770117" izz="0.041871103" />
        </inertial>
        -->
  </link>
  <joint name="l_ankle_swing_joint" type="revolute">
    <parent link="l_lower_leg_link"/>
    <origin rpy="3.14159265359 0 0" xyz="-0.071 -0.0145 0"/>
    <axis xyz="0 0 1"/>
    <child link="l_ankle_swing_link"/>
    <limit effort="10" lower="-2.0" upper="0.4" velocity="5.6548668"/>
  </joint>
  <link name="l_ankle_swing_link">
    <!-- Motor 15[r] 16[l] -->
    <visual>
      <geometry>
        <mesh filename="file:///home/mathieu/work/ros-kinetic/my-bioloid/src/bioloid_typea_description/assets/cad/AX-12_FCD-Conv_BDR-Col.dae" scale="0.001 0.001 0.001"/>
      </geometry>
      <origin rpy=" 3.14159265359  0.0 -1.57079632679" xyz="0 0 0"/>
    </visual>
    <visual>
      <geometry>
        <mesh filename="file:///home/mathieu/work/ros-kinetic/my-bioloid/src/bioloid_typea_description/assets/cad/FP04-F7_FCD-Conv_BDR-Col.dae" scale="0.001 0.001 0.001"/>
      </geometry>
      <origin rpy="3.14159265359 3.14159265359 0" xyz="0.0145 0.019 0"/>
    </visual>
    <!-- Motor 17[r] 18[l] -->
    <visual>
      <geometry>
        <mesh filename="file:///home/mathieu/work/ros-kinetic/my-bioloid/src/bioloid_typea_description/assets/cad/AX-12_FCD-Conv_BDR-Col.dae" scale="0.001 0.001 0.001"/>
      </geometry>
      <origin rpy="0 -1.57079632679 1.57079632679" xyz="0 -0.032 0"/>
    </visual>
    <visual>
      <geometry>
        <mesh filename="file:///home/mathieu/work/ros-kinetic/my-bioloid/src/bioloid_typea_description/assets/cad/FP04-F6_FCD-Conv_BDR-Col.dae" scale="0.001 0.001 0.001"/>
      </geometry>
      <origin rpy="1.57079632679 0 -1.57079632679" xyz="0.0145 -0.048 -0.019"/>
    </visual>
    <visual>
      <geometry>
        <mesh filename="file:///home/mathieu/work/ros-kinetic/my-bioloid/src/bioloid_typea_description/assets/cad/FP04-F6_FCD-Conv_BDR-Col.dae" scale="0.001 0.001 0.001"/>
      </geometry>
      <origin rpy="-1.57079632679 0 -1.57079632679" xyz="0.0145 -0.048 0.019"/>
    </visual>
    <collision name="r_ankle_swing_collision">
      <origin xyz="0.0135 -0.0167 0"/>
      <geometry>
        <box size="0.051 0.0721 0.04"/>
      </geometry>
    </collision>
    <inertial>
      <mass value="0.1370485873"/>
      <origin xyz="0.0175503800 0.0000382013 -0.0012148213"/>
      <inertia ixx="0.1126701697" ixy="-0.0091785729" ixz="-0.0436618956" iyy="0.9538828186" iyz="-0.0012283871" izz="0.9645318393"/>
    </inertial>
    <!--
        <inertial>
            <origin xyz="-0.000214 -0.018536 0.013873" />
            <mass value="0.16710792"/>
            <inertia ixx="0.12079175"  ixy="-0.00079781067"  ixz="-0.00039322246" iyx="-0.00079781067" iyy="0.10885465" iyz="0.0070770117" izx="-0.00039322246" izy="0.0070770117" izz="0.041871103" />
        </inertial>
        -->
  </link>
  <joint name="r_ankle_lateral_joint" type="revolute">
    <parent link="r_ankle_swing_link"/>
    <origin rpy="-1.57079632679 0 0" xyz="0 0 0"/>
    <axis xyz="0 0 1"/>
    <child link="r_ankle_lateral_link"/>
    <limit effort="10" lower="-0.5" upper="0.5" velocity="5.6548668"/>
  </joint>
  <link name="r_ankle_lateral_link">
    <visual>
      <geometry>
        <mesh filename="file:///home/mathieu/work/ros-kinetic/my-bioloid/src/bioloid_typea_description/assets/cad/BPF-BU_FCD-Conv_BDR-Col.dae" scale="0.001 0.001 0.001"/>
      </geometry>
      <origin rpy="1.57079632679 0 0" xyz="0 0 0.015"/>
    </visual>
    <visual>
      <geometry>
        <mesh filename="file:///home/mathieu/work/ros-kinetic/my-bioloid/src/bioloid_typea_description/assets/cad/FP04-F5_FCD-Conv_BDR-Col.dae" scale="0.001 0.001 0.001"/>
      </geometry>
      <origin rpy="-1.57079632679 -0.0  -1.57079632679" xyz="0 0 -0.0155"/>
    </visual>
    <collision name="r_ankle_lateral_collision">
      <origin xyz="0.009 0 -0.016"/>
      <geometry>
        <box size="0.0405 0.029 0.083"/>
      </geometry>
    </collision>
    <inertial>
      <mass value="0.0373560220"/>
      <origin xyz="-0.0055676472 0.0034398816 0.0028465215"/>
      <inertia ixx="0.1234423088" ixy="-0.0133733804" ixz="-0.0140420399" iyy="0.3516093267" iyz="0.0115251052" izz="0.4110130747"/>
    </inertial>
    <!--
        <inertial>
            <origin xyz="-0.025995 -0.009506 -0.000503" />
            <mass value="0.0794462"/>
            <inertia ixx="0.12079175"  ixy="-0.00079781067"  ixz="-0.00039322246" iyx="-0.00079781067" iyy="0.10885465" iyz="0.0070770117" izx="-0.00039322246" izy="0.0070770117" izz="0.041871103" />
        </inertial>
        -->
  </link>
  <joint name="l_ankle_lateral_joint" type="revolute">
    <parent link="l_ankle_swing_link"/>
    <origin rpy="-1.57079632679 0 0" xyz="0 0 0"/>
    <axis xyz="0 0 1"/>
    <child link="l_ankle_lateral_link"/>
    <limit effort="10" lower="-0.5" upper="0.5" velocity="5.6548668"/>
  </joint>
  <link name="l_ankle_lateral_link">
    <visual>
      <geometry>
        <mesh filename="file:///home/mathieu/work/ros-kinetic/my-bioloid/src/bioloid_typea_description/assets/cad/BPF-BU_FCD-Conv_BDR-Col.dae" scale="0.001 0.001 0.001"/>
      </geometry>
      <origin rpy="1.57079632679 0 0" xyz="0 0 0.015"/>
    </visual>
    <visual>
      <geometry>
        <mesh filename="file:///home/mathieu/work/ros-kinetic/my-bioloid/src/bioloid_typea_description/assets/cad/FP04-F5_FCD-Conv_BDR-Col.dae" scale="0.001 0.001 0.001"/>
      </geometry>
      <origin rpy="1.57079632679 3.14159265359  -1.57079632679" xyz="0 0 -0.0155"/>
    </visual>
    <collision name="r_ankle_lateral_collision">
      <origin xyz="-0.009 0 -0.016"/>
      <geometry>
        <box size="0.0405 0.029 0.083"/>
      </geometry>
    </collision>
    <inertial>
      <mass value="0.0373560220"/>
      <origin xyz="-0.0055676472 -0.0035014440 0.0028465215"/>
      <inertia ixx="0.1234378971" ixy="0.0133291996" ixz="-0.0140420399" iyy="0.3516092920" iyz="-0.0114926614" izz="0.4110086282"/>
    </inertial>
    <!--
        <inertial>
            <origin xyz="-0.025995 -0.009506 -0.000503" />
            <mass value="0.0794462"/>
            <inertia ixx="0.12079175"  ixy="-0.00079781067"  ixz="-0.00039322246" iyx="-0.00079781067" iyy="0.10885465" iyz="0.0070770117" izx="-0.00039322246" izy="0.0070770117" izz="0.041871103" />
        </inertial>
        -->
  </link>
  <joint name="r_foot_joint" type="fixed">
    <parent link="r_ankle_lateral_link"/>
    <origin rpy="0 0 0" xyz="0 0 0"/>
    <child link="r_foot_link"/>
  </joint>
  <gazebo reference="r_foot_link">
    <mu1>9000</mu1>
    <mu2>9000</mu2>
    <kp>1000000.0</kp>
    <kd>10.0</kd>
    <minDepth>0.001</minDepth>
    <maxContacts>1</maxContacts>
  </gazebo>
  <joint name="l_foot_joint" type="fixed">
    <parent link="l_ankle_lateral_link"/>
    <origin rpy="0 0 0" xyz="0 0 0"/>
    <child link="l_foot_link"/>
  </joint>
  <gazebo reference="l_foot_link">
    <mu1>9000</mu1>
    <mu2>9000</mu2>
    <kp>1000000.0</kp>
    <kd>10.0</kd>
    <minDepth>0.001</minDepth>
    <maxContacts>1</maxContacts>
  </gazebo>
</robot>
